Workbook
Name Action: '[1]Data Call Management'!$A$3:$A$12
Name Action: '[1]Data Call Management'!$A$3:$A$12
Name Action: '[1]Data Call Management'!$A$3:$A$12
Name Action: '[1]Data Call Management'!$A$3:$A$12
Name Action: '[1]Data Call Management'!$A$3:$A$12
Name Action: '[1]Data Call Management'!$A$3:$A$12
Name Action: '[1]Data Call Management'!$A$3:$A$12
Name Action: '[1]Data Call Management'!$A$3:$A$12
Name Action: '[1]Data Call Management'!$A$3:$A$12
Name Action: '[1]Data Call Management'!$A$3:$A$12
Name Action: '[1]Data Call Management'!$A$3:$A$12
Name Action: '[1]Data Call Management'!$A$3:$A$12
Name Action: '[1]Data Call Management'!$A$3:$A$12
Name Action: [2]Reference!$A$3:$A$12
Name Action: '[1]Data Call Management'!$A$3:$A$12
Name Action: [3]Reference!$A$3:$A$12
Name Action: '[1]Data Call Management'!$A$3:$A$12
Name Action: [2]Reference!$A$3:$A$12
Name Crit: [4]Reference!$D$3:$D$18
Name Critical: '[1]Data Call Management'!$B$3:$B$18
Name Critical: '[1]Data Call Management'!$B$3:$B$18
Name Critical: '[1]Data Call Management'!$B$3:$B$18
Name Critical: '[1]Data Call Management'!$B$3:$B$18
Name Critical: '[1]Data Call Management'!$B$3:$B$18
Name Critical: '[1]Data Call Management'!$B$3:$B$18
Name Critical: '[1]Data Call Management'!$B$3:$B$18
Name Critical: '[1]Data Call Management'!$B$3:$B$18
Name Critical: '[1]Data Call Management'!$B$3:$B$18
Name Critical: '[1]Data Call Management'!$B$3:$B$18
Name Critical: '[1]Data Call Management'!$B$3:$B$18
Name Critical: '[1]Data Call Management'!$B$3:$B$18
Name Critical: '[1]Data Call Management'!$B$3:$B$18
Name Critical: [2]Reference!$B$3:$B$18
Name Critical: '[1]Data Call Management'!$B$3:$B$18
Name Critical: [3]Reference!$B$3:$B$18
Name Critical: '[1]Data Call Management'!$B$3:$B$18
Name Critical: [2]Reference!$B$3:$B$18
Name CVTTable: #REF!
Name CVTTable: TEMP!$C$3:$W$235
Name CVTTable: 'CVT Master List'!$C$4:$W$248
Name PriorityRange: #REF!
Name PriorityRange: TEMP!$S$3:$U$84
Name PriorityRange: 'CVT Master List'!$S$5:$U$97
Name WSMS_108: #REF!
Name WSMS_108: #REF!
Name WSMS_108: #REF!
Name WSMS_108: #REF!
Name WSMS_108: #REF!
Name WSMS_108: #REF!
Name WSMS_108: #REF!
Name WSMS_108: #REF!
Name WSMS_108: #REF!
Name WSMS_108: #REF!
Name WSMS_108: #REF!
Name WSMS_108: #REF!
Name WSMS_108: #REF!
Name WSMS_108: #REF!
Name WSMS_108: #REF!
Name WSMS_108: #REF!
Name WSMS_108: #REF!

Sheet DELETE Comments 
A1: Comment # | B1: Scenario | C1: Tab | D1: CVT No | E1: Step No | F1: Pass | G1: 1 | H1: 2 | I1: 3 | J1: 4 | K1: 5 | L1: Comment | M1: Submit By | N1: Sub Date | O1: Status | P1: Resolution Type | Q1: Resolution
A2: 1 | B2: 4.4 | C2: File Maintenance | D2: FS10 | E2: 1 | F2: P | L2: Please list the "appropriate column" that the tester must verify. | M2: AMR | N2: 40106 | O2: Retest | P2: CVT | Q2: Changed step to "select row" to update funding
A3: 2 | B3: 4.4 | C3: File Maintenance | D3: FS10 | E3: 2 | K3: F | L3: What values should be displaying for a particular PCN/Task. For example, the dollar amounts are based on your filter. | M3: AMR | N3: 40106 | O3: Retest | P3: CVT | Q3: Added note that totals are limited by filter applied
A4: 3 | B4: 4.4 | C4: File Maintenance | D4: FS10 | E4: 2 | K4: F | L4: Not working. I didn't think we were testing this yet. | M4: AMR | N4: 40106 | O4: Retest | P4: CVT | Q4: Removed
A5: 4 | B5: 4.4 | C5: File Maintenance | D5: FS10 | E5: 3 | K5: F | L5: Straggler step | M5: AMR | N5: 40106 | O5: Retest | P5: CVT | Q5: Removed - straggler step
A6: 5 | B6: 4.4 | C6: File Maintenance | D6: FS10 | E6: 3 | K6: F | L6: Tester wasn't required to make any changes to the Funds Spread. Cannot click "save." | M6: AMR | N6: 40106 | O6: Retest | P6: CVT | Q6: Added step to edit a fund spread amount
A7: 6 | B7: 4.4 | C7: File Maintenance | D7: FS10 | E7: 4 | F7: P | L7: Shouldn't they be reviewing the peace target to the peace funded? Why are they comparing to the target reference or ABIDES? | M7: AMR | N7: 40106 | O7: Retest | P7: CVT | Q7: Replaced with "Review the Summary Totals at the top of the grid to compare funding to requirements."
A8: 7 | B8: 4.4 | C8: File Maintenance | D8: FS10 | E8: 5 | F8: P | L8: When I clicked on excess funding, it resorted the PCNs. Items that had requirements unfunded showed up on the list, but were near the bottom. Should they be showing up? Also, I don't think there shouldn't be any excess funding in a FYDP data call. System won't let you overfund requirements. | M8: AMR | N8: 40106 | O8: Open | P8: Question | Q8: The Excess funding option should not be visible within FYDP
A9: 8 | B9: 4.4 | C9: File Maintenance | D9: FS10 | E9: 6 | F9: P | L9: Suggestion: specify that it is the refresh button next to the Funds Spread Drop Down. There is another refresh at the top lefthand corner of the page. | M9: AMR | N9: 40106 | O9: Retest | P9: CVT | Q9: Updated verbiage
A10: 9 | B10: 4.4 | C10: File Maintenance | D10: FS10 | E10: PRE | K10: F | L10: Suggestion: List steps to determine if data is in input or verification status. Also, isn't the data call either "Closed" or "Open." I thought we got rid of the different statuses. | M10: AMR | N10: 40106 | O10: Retest | P10: CVT | Q10: Removed 'status' comment, used this space to explain why user would be doing this.
A11: 10 | B11: 4.4 | C11: File Maintenance | D11: FS4 | E11: 3 | K11: F | L11: Actual radial button is labeled "Fully Fund to Target by Priority." | M11: AMR | N11: 40106 | O11: Retest | P11: CVT | Q11: Added "by priority"
A12: 11 | B12: 4.4 | C12: File Maintenance | D12: FS4 | E12: 4 | F12: P | L12: Suggestion: Reference that the appropriate data call must be chosen as well as the desired year. | M12: AMR | N12: 40106 | O12: Retest | P12: CVT | Q12: Add note to select data call and year.
A13: 12 | B13: 4.4 | C13: File Maintenance | D13: FS4 | E13: 5 | G13: F | L13: Must first choose a Mass Change Option (Peace or Supplemental) before saving. For CVT purposes, I chose both Peace and Supplemental and clicked save. | M13: AMR | N13: 40106 | O13: Retest | P13: CVT | Q13: Add note to select peace, supp or both
A14: 13 | B14: 4.4 | C14: File Maintenance | D14: FS4 | E14: PRE | F14: P | L14: Suggestion: List steps to check that Target has been inputted or list CVT test that shows how you check target. | M14: AMR | N14: 40106 | O14: Retest | P14: CVT | Q14: Referenced CVT TGT7
A15: 14 | B15: 4.4 | C15: File Maintenance | D15: NAV1 | E15: 5 | F15: Pass | L15: Please specify "Data Call" name for CVT purposes. | M15: AMR | N15: 40106 | O15: Retest | P15: CVT | Q15: Updated step to state: Select Data Call. Reference scenario / data call instructions for specific data call to select. Will also clarify on scenarios
A16: 15 | B16: 4.4 | C16: File Maintenance | D16: NAV2 | E16: 2 | F16: Pass | L16: FYDP Data Call Tools. | M16: AMR | N16: 40106 | O16: Retest | P16: CVT | Q16: Updated comment
A17: 16 | B17: 4.4 | C17: File Maintenance | D17: NAV2 | E17: 2 | F17: P | L17: FYDP Data Call Tools. | M17: AMR | N17: 40106 | O17: Retest | P17: CVT | Q17: Added "Data Call"
A18: 17 | B18: 4.4 | C18: File Maintenance | D18: NAV2 | E18: 9 | F18: Pass | L18: Please change to QM Requirement | M18: AMR | N18: 40106 | O18: Retest | P18: CVT | Q18: Fixed Typo
A19: 18 | B19: 4.4 | C19: File Maintenance | D19: NAV2 | E19: NOTE | F19: P | L19: Suggestion: Please add Program Group, PEC, and AFFEIC in parentheses. This will give them a parameter for filtering, which is helpful for people who do not typically use FRM. | M19: AMR | N19: 40106 | O19: Retest | P19: CVT | Q19: updated note
A20: 19 | B20: 4.4 | C20: File Maintenance | D20: NAV4 | E20: 1 | F20: P | L20: FYDP Data Call Tools. | M20: AMR | N20: 40106 | O20: Retest | P20: CVT | Q20: Added "Data Call"
A21: 20 | B21: 4.4 | C21: File Maintenance | D21: NAV4 | E21: 3 | F21: P | L21: Should already have filters from NAV2. | M21: AMR | N21: 40106 | O21: Retest | P21: CVT | Q21: Removed step
A22: 21 | B22: 4.4 | C22: File Maintenance | D22: RPT1 | E22: 2 | F22: Pass | L22: FYDP Data Call Tools | M22: AMR | N22: 40106 | O22: Retest | P22: CVT | Q22: Updated CVT
A23: 22 | B23: 4.4 | C23: File Maintenance | D23: RPT1 | E23: 6 | F23: Pass | L23: Suggestion: Check Program Group, PEC, and AFEEIC | M23: AMR | N23: 40106 | O23: Retest | P23: CVT | Q23: Done
A24: 23 | B24: 4.4 | C24: File Maintenance | D24: RPT1 | E24: 7 | J24: F | L24: This should be on the Execution Custom Datasheet not the FYDP. | M24: AMR | N24: 40106 | O24: Retest | P24: CVT | Q24: Deleted
A25: 24 | B25: 4.4 | C25: File Maintenance | D25: RPT1 | E25: 8 | F25: F | L25: This should be on the Execution Custom Datasheet not the FYDP. | M25: AMR | N25: 40106 | O25: Retest | P25: CVT | Q25: Deleted
A26: 25 | B26: 4.4 | C26: File Maintenance | D26: RPT1 | E26: 9 | F26: F | L26: This should be on the Execution Custom Datasheet not the FYDP. | M26: AMR | N26: 40106 | O26: Retest | P26: CVT | Q26: Deleted
A27: 26 | B27: 4.4 | C27: File Maintenance | D27: RPT1 | E27: 10 | F27: Pass | L27: Suggestion: Tester should make sure that Amount and a year are checked under Cost Type and Years. | M27: AMR | N27: 40106 | O27: Retest | P27: CVT | Q27: Added note
A28: 27 | B28: 4.4 | C28: File Maintenance | D28: RPT1 | E28: 11 | I28: F | L28: There isn't a button to "Preview Datasheet." Should be "Export Data to Excel." | M28: AMR | N28: 40106 | O28: Retest | P28: CVT | Q28: Done
A29: 28 | B29: 4.4 | C29: File Maintenance | D29: RPT1 | E29: 12 | G29: f | L29: I clicked on download report. Once loading was complete, I was never prompted to open a spreadsheet even though I gave permission to download file. Spreadsheet never opened even though I had excel already open. (I tried three times) Also, I would like to see another step to verify that the report actually pulled what it was supposed to. | M29: AMR | N29: 40106 | O29: ITI Test | P29: Bug | Q29: Updated steps for new navigation due to report queue. Pop up is still an issue
A30: 29 | B30: 2.6 | C30: User Mgmt | D30: DC1 | E30: 3 | F30: P | L30: Is it necessary to check one or the other for the purposes of this CVT? | M30: AMR | N30: 40106 | O30: Retest | P30: CVT | Q30: Added "active for purpose of this CVT"
A31: 30 | B31: 2.6 | C31: User Mgmt | D31: DC1 | E31: 5.A | F31: P | L31: Suggestion: Have them choose a paticular data call from the list for CVT purposes. | M31: AMR | N31: 40106 | O31: Retest | P31: CVT | Q31: Added to Scenario
A32: 31 | B32: 2.6 | C32: User Mgmt | D32: DC1 | E32: 5.C | F32: P | L32: Suggestion: Identify what needs to be selected. For example, radial button needs to be selected under RQMT option? It might make a difference what parameters are selected. | M32: AMR | N32: 40106 | O32: Retest | P32: CVT | Q32: Added to Scenario
A33: 32 | B33: 2.6 | C33: User Mgmt | D33: DC1 | E33: 6.A | F33: P | L33: What parameters should be selected based on quick copy data call? | M33: AMR | N33: 40106 | O33: Retest | P33: CVT | Q33: Added to Scenario
A34: 33 | B34: 2.6 | C34: User Mgmt | D34: DC1 | E34: 7.B | F34: P | L34: Cannot change Source Data Call data. Users have the ability to change Destination Data Call only. Please take out edit/update as desired. Also, the Source Data Call grid only shows the year and source rqmt. Data Call and Data Set are not there. | M34: AMR | N34: 40106 | O34: Retest | P34: CVT | Q34: Removed "edit / update" and "data call and data set
A35: 34 | B35: 2.6 | C35: User Mgmt | D35: DC1 | E35: 8.A | F35: P | L35: Note: Should keep all boxes checked to finish CVT. | M35: AMR | N35: 40106 | O35: Retest | P35: CVT | Q35: Added Note
A36: 35 | B36: 2.6 | C36: User Mgmt | D36: DC4 | E36: PRE | L36: Remove year function forth coming. | M36: AMR | N36: 40106 | O36: Retest | P36: CVT | Q36: Removed comment
A37: 36 | B37: 2.6 | C37: User Mgmt | D37: DC5 | E37: 1 | K37: F | L37: Please state that this is the data call that was just created. It is unclear if it is any data call or the one that was created. | M37: AMR | N37: 40106 | O37: Retest | P37: CVT | Q37: Added "Note: When using this function to validate a newly created data call, select the newly created data call and the source data call for the comparison
A38: 37 | B38: 2.6 | C38: User Mgmt | D38: DC5 | E38: 3 | F38: P | L38: This should be the data call you copied from. | M38: AMR | N38: 40106 | O38: Retest | P38: CVT | Q38: Added "Note: When using this function to validate a newly created data call, select the newly created data call and the source data call for the comparison"
A39: 38 | B39: 2.6 | C39: User Mgmt | D39: DC5 | E39: 4 | F39: P | L39: Refresh next to Audit Data Call. There is another refresh at the top, left corner of the screen. | M39: AMR | N39: 40106 | O39: Retest | P39: CVT | Q39: Added next to "Audit Data Call"
A40: 39 | B40: 2.6 | C40: User Mgmt | D40: DC5 | E40: 5 | G40: F | L40: Both the data call I created and the data call I copied have RQMTS of zero. When I checked the RQMTs of the TEST Exec, it had RQMTS. I chose the radial option "Use Data Call RQMT" in STEP 1: Data Call Options when I created my data call. Also, I left the "Load RQMTS" checked in Step 4 of the create Data Call. | M40: AMR | N40: 40106 | O40: Assigned | P40: BUG | Q40: BUG
...

Sheet Index
A2: INDEX | C2: 13.2 RELEASE TABS LEGEND | D2: ABOUT
A3: I3 - CVT Master | C3: Pink Tab = Index | D3: ECT - Electronic Case Tracking
A4: (BT44) WWD Memos | C4: Blue Tab = CVT Master
A5: (BT44) IRILO Memos | C5: Orange Tabs = Workflows: WWD Memos, IRILO Memos, MEB Memos, BMT, Informal LOD,
A6: (BT44) MEB Memos | C6: Participation Waiver, Medical Holds, Deployment Waiver, Non Emergent Surgery,
A7: (BT44) BMT WF | C7: Modifications, BCMR, Congressionals, PEPP, Full Search | D7: Version: | E7: 1
A8: Informal LOD | C8: Brown Tab = Common Tools
A9: (BT44) Participation Waiver WF
A10: (BT44) Medical Holds WF | D10: Date: | E10: 41865
A11: (BT44) Deployment Waiver WF
A12: (BT44) Non Emergent Surgery WF
A13: (BT44) Modification WF
A14: (BT44) BCMR WF
A15: (BT44) Congressionals WF
A16: (BT44) PEPP WF
A17: Full Search
A18: TC Common Tools
A24: Status Levels: Requirement or CVT Script
A25: Level | B25: Title | C25: Definition
A27: IP-1 | B27: Development Testing | C27: IP-1: Contractor will provides test materials to test director. The Test Director reviews all test materials and reviews application functionality for functional fit. All test results are compiled and analyzed. The Test Director will approve the release for the next IP based on agreed-upon business rules.
A28: IP-2 | B28: Integration Testing | C28: IP-2: Testing is extended to the test manager. The test manager will perform testing and denote defects using the same methodology used in IP-1. Test results are forwarded to the Test Director. The Test Director will review problem reports and provide direction to ITI based on the failure criticality and requirement priority. When testing aligns with agreed-upon business rules, the Test Director will approve the release for Customer Acceptance Testing.
A29: IP-3 | B29: System Testing | C29: IP-3: During IP-3 Testing, the test group is expanded to a broad set of users selected by the test managers time in the production-simulated environment. Testing is performed with defects denoted using the same methodology used in IP-1/IP-2. Test results are forwarded to ITI and the Test Director for analysis and interpretation. When testing aligns with agreed-upon business rules, the Test Director will approve the testing activities and recommend the release for approval by the LCMB.
A32: MIL-STD-498 DR Definitions
A34: Failure - Cannot proceed to the next step.
A35: Failure | B35: 1a | C35: Prevent the accomplishment of an operational or mission essential capability.
B36: 1b | C36: Jeopardize safety, security, or other requirements designated "critical"
B37: 2a | C37: Adversely affects the accomplishment of an operational or mission essential capability and no work-around solution is known
B38: 2b | C38: Adversely affects technical, cost, or schedule risks to the project or to life cycle support of the system, and no work-around solution
A39: Acceptable: Problems identified but able to advance to the next step.
A40: Acceptable | B40: 3a | C40: Adversely affects the accomplishment of an operation or mission essential capability but a work-around solution is known
B41: 3b | C41: Adversely affects technical, cost or schedule risks to the project or to life cycle support of the system, but a work-around solution is known
B42: 4a | C42: Results in user/operator inconvenience or annoyance but does not affect a required operational or mission essential capability
B43: 4b | C43: Results in inconvenience or annoyance for development or support personnel but does not prevent the accomplishment of those responsibilities.
B44: 5 | C44: Any other effect
A48: Script Status Definitions
A50: P | B50: Pass | C50: CVT Passes; no DRs received.
A51: A | B51: Acceptable | C51: Deficiencies identified but work around exists.
A52: F | B52: Fail | C52: Work Stoppage has been encountered
A53: 0 | B53: Not Tested | C53: CVT is available, but results do not exist due to "in-work" or testing has not started.

Sheet CVT Master List
A1: Audit - Customer Verification Test (CVT)
A2: RQMT # | B2: Priority | C2: CVT | D2: CVT Script Title | E2: Test Status | F2: IP-1 Pass Date | G2: IP-2 Pass Date | H2: IP-3 Pass Date | I2: CVT Status FYDP | M2: CVT Status (NT,A,P,F) | N2: DR # | V2: Comment | W2: CR #, if applicable
J3: Critical | K3: Major | L3: Minor | N3: 1 | O3: 2 | P3: 3 | Q3: 4 | R3: 5 | S3: Critical | T3: Major | U3: Minor
D4: Navigation
A5: FRM 4.3. FRM 4.27 | B5: Major | C5: NAV1 | D5: Select a Data Call | E5: Ready | I5: P | J5: =IF($B5=J$3,$I5,"") | K5: =IF($B5=K$3,$I5,"") -> P | L5: =IF($B5=L$3,$I5,"") | M5: P | S5: =IF($B5=S$3,$M5,"") | T5: =IF($B5=T$3,$M5,"") -> P | U5: =IF($B5=U$3,$M5,"")
A6: N/A | B6: Major | C6: NAV2 | D6: FRM Sections: (Navigate to Inputs, Data Sheet Views, Reports) | E6: Ready | I6: P | J6: =IF($B6=J$3,$I6,"") | K6: =IF($B6=K$3,$I6,"") -> P | L6: =IF($B6=L$3,$I6,"") | M6: P | S6: =IF($B6=S$3,$M6,"") | T6: =IF($B6=T$3,$M6,"") -> P | U6: =IF($B6=U$3,$M6,"") | V6: CVT Updates Applied
A7: FM 5.1-5.2 | B7: Major | C7: NAV3 | D7: Navigate to "Target Maintenance" | E7: Ready | I7: P | J7: =IF($B7=J$3,$I7,"") | K7: =IF($B7=K$3,$I7,"") -> P | L7: =IF($B7=L$3,$I7,"") | M7: P | S7: =IF($B7=S$3,$M7,"") | T7: =IF($B7=T$3,$M7,"") -> P | U7: =IF($B7=U$3,$M7,"") | V7: CVT Updates Applied
A8: FRM 6.1-6.2 | B8: Critical | C8: NAV4 | D8: Navigate to "QM Funds Spread" | E8: Ready | I8: P | J8: =IF($B8=J$3,$I8,"") -> P | K8: =IF($B8=K$3,$I8,"") | L8: =IF($B8=L$3,$I8,"") | M8: P | N8: X | R8: X | S8: =IF($B8=S$3,$M8,"") -> P | T8: =IF($B8=T$3,$M8,"") | U8: =IF($B8=U$3,$M8,"") | V8: CVT Updates Applied
A9: FRM 7.1 | B9: Critical | C9: NAV5 | D9: RQMT ADJUSTMENT: QM (Quick Maintenance) Requirement: Access Grid | E9: Ready | I9: P | J9: =IF($B9=J$3,$I9,"") -> P | K9: =IF($B9=K$3,$I9,"") | L9: =IF($B9=L$3,$I9,"") | M9: P | N9: X | S9: =IF($B9=S$3,$M9,"") -> P | T9: =IF($B9=T$3,$M9,"") | U9: =IF($B9=U$3,$M9,"")
D10: User Mgmt
A11: - | B11: Critical | C11: UM1 | D11: FRM Basics: Register for FRM | E11: Ready | I11: N/A | J11: =IF($B11=J$3,$I11,"") -> N/A | K11: =IF($B11=K$3,$I11,"") | L11: =IF($B11=L$3,$I11,"") | M11: N/A | S11: =IF($B11=S$3,$M11,"") -> N/A | T11: =IF($B11=T$3,$M11,"") | U11: =IF($B11=U$3,$M11,"") | V11: Recommend removing from this test agenda
A12: FRM 1.1 - 1.5 | B12: Critical | C12: UM2 | D12: Activate User (Generic) | E12: Ready | I12: P | J12: =IF($B12=J$3,$I12,"") -> P | K12: =IF($B12=K$3,$I12,"") | L12: =IF($B12=L$3,$I12,"") | M12: P | S12: =IF($B12=S$3,$M12,"") -> P | T12: =IF($B12=T$3,$M12,"") | U12: =IF($B12=U$3,$M12,"")
A13: FRM 1.1 - 1.5 | B13: Critical | C13: UM3 | D13: Confirm Activated User | E13: Ready | I13: P | J13: =IF($B13=J$3,$I13,"") -> P | K13: =IF($B13=K$3,$I13,"") | L13: =IF($B13=L$3,$I13,"") | M13: P | S13: =IF($B13=S$3,$M13,"") -> P | T13: =IF($B13=T$3,$M13,"") | U13: =IF($B13=U$3,$M13,"")
A14: FRM 1.1 - 1.5 | B14: Critical | C14: UM4 | D14: Confirm Filter | E14: Ready | I14: R | J14: =IF($B14=J$3,$I14,"") -> R | K14: =IF($B14=K$3,$I14,"") | L14: =IF($B14=L$3,$I14,"") | M14: R | S14: =IF($B14=S$3,$M14,"") -> R | T14: =IF($B14=T$3,$M14,"") | U14: =IF($B14=U$3,$M14,"") | V14: Change to be made to add PEC
A15: FRM 1.1 - 1.5 | B15: Major | C15: UM5 | D15: Confirm User Management Roles | E15: Ready | I15: P | J15: =IF($B15=J$3,$I15,"") | K15: =IF($B15=K$3,$I15,"") -> P | L15: =IF($B15=L$3,$I15,"") | M15: P | S15: =IF($B15=S$3,$M15,"") | T15: =IF($B15=T$3,$M15,"") -> P | U15: =IF($B15=U$3,$M15,"")
D16: Data Call Roles
A17: 4.8, 1.1, 1.2 | B17: Critical | C17: DCROLE1 | D17: Manage Roles and Responsibility | E17: Ready | I17: P | J17: =IF($B17=J$3,$I17,"") -> P | K17: =IF($B17=K$3,$I17,"") | L17: =IF($B17=L$3,$I17,"") | M17: P | S17: =IF($B17=S$3,$M17,"") -> P | T17: =IF($B17=T$3,$M17,"") | U17: =IF($B17=U$3,$M17,"")
A18: 4.8 | B18: Major | C18: DCROLE2 | D18: Review Roles and Responsibilities by Users | E18: Ready | I18: P | J18: =IF($B18=J$3,$I18,"") | K18: =IF($B18=K$3,$I18,"") -> P | L18: =IF($B18=L$3,$I18,"") | M18: P | S18: =IF($B18=S$3,$M18,"") | T18: =IF($B18=T$3,$M18,"") -> P | U18: =IF($B18=U$3,$M18,"")
A19: 4.8, 4.12 | B19: Major | C19: DCROLE3 | D19: Review Roles and Responsibilities by Affiliation | E19: Ready | I19: P | J19: =IF($B19=J$3,$I19,"") | K19: =IF($B19=K$3,$I19,"") -> P | L19: =IF($B19=L$3,$I19,"") | M19: P | S19: =IF($B19=S$3,$M19,"") | T19: =IF($B19=T$3,$M19,"") -> P | U19: =IF($B19=U$3,$M19,"")
A20: 2.3 | B20: Critical | C20: DCROLE4 | D20: Search for User | E20: Ready | I20: P | J20: =IF($B20=J$3,$I20,"") -> P | K20: =IF($B20=K$3,$I20,"") | L20: =IF($B20=L$3,$I20,"") | M20: P | S20: =IF($B20=S$3,$M20,"") -> P | T20: =IF($B20=T$3,$M20,"") | U20: =IF($B20=U$3,$M20,"")
A21: 4.4, 4.8 | B21: Major | C21: DCROLE5 | D21: Mass Change User Roles - Add Roles | E21: Ready | I21: P | J21: =IF($B21=J$3,$I21,"") | K21: =IF($B21=K$3,$I21,"") -> P | L21: =IF($B21=L$3,$I21,"") | M21: P | S21: =IF($B21=S$3,$M21,"") | T21: =IF($B21=T$3,$M21,"") -> P | U21: =IF($B21=U$3,$M21,"")
A22: 4.4, 4.8 | B22: Major | C22: DCROLE6 | D22: Mass Change User Roles - Remove Roles | E22: Ready | I22: P | J22: =IF($B22=J$3,$I22,"") | K22: =IF($B22=K$3,$I22,"") -> P | L22: =IF($B22=L$3,$I22,"") | M22: P | S22: =IF($B22=S$3,$M22,"") | T22: =IF($B22=T$3,$M22,"") -> P | U22: =IF($B22=U$3,$M22,"")
D23: Create Data Call
A24: 4.9, 4.10 | B24: Critical | C24: DC1 | D24: Create Execution Data Call | E24: unpredictable results | I24: Data call | J24: =IF($B24=J$3,$I24,"") -> Data call | K24: =IF($B24=K$3,$I24,"") | L24: =IF($B24=L$3,$I24,"") | M24: NT | S24: =IF($B24=S$3,$M24,"") -> NT | T24: =IF($B24=T$3,$M24,"") | U24: =IF($B24=U$3,$M24,"")
A25: 4.9, 4.10 | B25: Critical | C25: DC2 | D25: Create FYDP FRM Data Call | E25: unpredictable results | I25: Data call | J25: =IF($B25=J$3,$I25,"") -> Data call | K25: =IF($B25=K$3,$I25,"") | L25: =IF($B25=L$3,$I25,"") | M25: NT | S25: =IF($B25=S$3,$M25,"") -> NT | T25: =IF($B25=T$3,$M25,"") | U25: =IF($B25=U$3,$M25,"")
A26: FRM 4.12, 4.15-4.17 | B26: Critical | C26: DC3 | D26: Review Data Call Options | E26: Ready | I26: R | J26: =IF($B26=J$3,$I26,"") -> R | K26: =IF($B26=K$3,$I26,"") | L26: =IF($B26=L$3,$I26,"") | M26: R | S26: =IF($B26=S$3,$M26,"") -> R | T26: =IF($B26=T$3,$M26,"") | U26: =IF($B26=U$3,$M26,"") | V26: CVT updates applied
A27: FRM 4.11 | B27: Critical | C27: DC4 | D27: Add Years to Data Call | E27: Ready | I27: Data call | J27: =IF($B27=J$3,$I27,"") -> Data call | K27: =IF($B27=K$3,$I27,"") | L27: =IF($B27=L$3,$I27,"") | M27: NT | S27: =IF($B27=S$3,$M27,"") -> NT | T27: =IF($B27=T$3,$M27,"") | U27: =IF($B27=U$3,$M27,"")
A28: FRM 7.6, 4.2 | B28: Critical | C28: DC5 | D28: Audit Requirement | E28: Ready | I28: Data call | J28: =IF($B28=J$3,$I28,"") -> Data call | K28: =IF($B28=K$3,$I28,"") | L28: =IF($B28=L$3,$I28,"") | M28: NT | S28: =IF($B28=S$3,$M28,"") -> NT | T28: =IF($B28=T$3,$M28,"") | U28: =IF($B28=U$3,$M28,"")
A29: FRM 5.6 | B29: Major | C29: DC6 | D29: Audit Target | E29: Ready | I29: Data call | J29: =IF($B29=J$3,$I29,"") | K29: =IF($B29=K$3,$I29,"") -> Data call | L29: =IF($B29=L$3,$I29,"") | M29: NT | S29: =IF($B29=S$3,$M29,"") | T29: =IF($B29=T$3,$M29,"") -> NT | U29: =IF($B29=U$3,$M29,"")
A30: FRM 6.8, FRM 6.9 | B30: Major | C30: DC7 | D30: Audit Funds Spread | E30: Ready | I30: Data call | J30: =IF($B30=J$3,$I30,"") | K30: =IF($B30=K$3,$I30,"") -> Data call | L30: =IF($B30=L$3,$I30,"") | M30: NT | S30: =IF($B30=S$3,$M30,"") | T30: =IF($B30=T$3,$M30,"") -> NT | U30: =IF($B30=U$3,$M30,"")
A31: Missing | B31: Minor | C31: DC8 | D31: Delete Data Call | E31: Ready | I31: Data call | J31: =IF($B31=J$3,$I31,"") | K31: =IF($B31=K$3,$I31,"") | L31: =IF($B31=L$3,$I31,"") -> Data call | M31: NT | S31: =IF($B31=S$3,$M31,"") | T31: =IF($B31=T$3,$M31,"") | U31: =IF($B31=U$3,$M31,"") -> NT
A32: 4.8,4.4 | B32: Major | C32: DC9 | D32: Certify Data Call Ready for File Maintenance | E32: Ready | I32: Data call | J32: =IF($B32=J$3,$I32,"") | K32: =IF($B32=K$3,$I32,"") -> Data call | L32: =IF($B32=L$3,$I32,"") | M32: NT | S32: =IF($B32=S$3,$M32,"") | T32: =IF($B32=T$3,$M32,"") -> NT | U32: =IF($B32=U$3,$M32,"")
A33: 4.4, 5.12, 6.11 | B33: Critical | C33: DC10 | D33: Close Data Call | E33: Ready | I33: Data call | J33: =IF($B33=J$3,$I33,"") -> Data call | K33: =IF($B33=K$3,$I33,"") | L33: =IF($B33=L$3,$I33,"") | M33: NT | S33: =IF($B33=S$3,$M33,"") -> NT | T33: =IF($B33=T$3,$M33,"") | U33: =IF($B33=U$3,$M33,"")
D34: Prepare Data Call Data
A35: FRM 4.4, 4.13, 6.3 | B35: Major | C35: MassDC1 | D35: Overlay DC Funding | E35: DUPLICATE | I35: DUP | J35: =IF($B35=J$3,$I35,"") | K35: =IF($B35=K$3,$I35,"") -> DUP | L35: =IF($B35=L$3,$I35,"") | M35: DUP | S35: =IF($B35=S$3,$M35,"") | T35: =IF($B35=T$3,$M35,"") -> DUP | U35: =IF($B35=U$3,$M35,"") | V35: =+"Refer to FS9, Status: "& M64 -> Refer to FS9, Status: P
A36: FRM 4.4, 4.13 | B36: Major | C36: MassDC2 | D36: Mass Change: Update Status | E36: Ready | I36: NA | J36: =IF($B36=J$3,$I36,"") | K36: =IF($B36=K$3,$I36,"") -> NA | L36: =IF($B36=L$3,$I36,"") | M36: NA | S36: =IF($B36=S$3,$M36,"") | T36: =IF($B36=T$3,$M36,"") -> NA | U36: =IF($B36=U$3,$M36,"")
A37: FRM 4.4, 4.13, 6.3 | B37: Major | C37: MassDC3 | D37: Mass Change: 70% Spread to Target by Priority | E37: DUPLICATE | I37: DUP | J37: =IF($B37=J$3,$I37,"") | K37: =IF($B37=K$3,$I37,"") -> DUP | L37: =IF($B37=L$3,$I37,"") | M37: DUP | S37: =IF($B37=S$3,$M37,"") | T37: =IF($B37=T$3,$M37,"") -> DUP | U37: =IF($B37=U$3,$M37,"") | V37: =+"Refer to FS3, Status: "& +M58 -> Refer to FS3, Status: R
A38: FRM 4.4, 4.13, 6.3 | B38: Critical | C38: MassDC4 | D38: Mass Change: Fully Fund to Target | E38: DUPLICATE | I38: DUP | J38: =IF($B38=J$3,$I38,"") -> DUP | K38: =IF($B38=K$3,$I38,"") | L38: =IF($B38=L$3,$I38,"") | M38: DUP | S38: =IF($B38=S$3,$M38,"") -> DUP | T38: =IF($B38=T$3,$M38,"") | U38: =IF($B38=U$3,$M38,"") | V38: =+"Refer to FS4, Status: "& +M59 -> Refer to FS4, Status: P
A39: FRM 4.4, 4.13, 6.3 | B39: Major | C39: MassDC5 | D39: Mass Change: OP30 Spread; next 70% Spread to Target by Priority | E39: DUPLICATE | I39: DUP | J39: =IF($B39=J$3,$I39,"") | K39: =IF($B39=K$3,$I39,"") -> DUP | L39: =IF($B39=L$3,$I39,"") | M39: DUP | S39: =IF($B39=S$3,$M39,"") | T39: =IF($B39=T$3,$M39,"") -> DUP | U39: =IF($B39=U$3,$M39,"") | V39: =+"Refer to FS5, Status: "& +M60 -> Refer to FS5, Status: R
A40: FRM 4.4, 4.13, 6.3 | B40: Major | C40: MassDC6 | D40: Mass Change: Fully Fund | E40: DUPLICATE | I40: DUP | J40: =IF($B40=J$3,$I40,"") | K40: =IF($B40=K$3,$I40,"") -> DUP | L40: =IF($B40=L$3,$I40,"") | M40: DUP | S40: =IF($B40=S$3,$M40,"") | T40: =IF($B40=T$3,$M40,"") -> DUP | U40: =IF($B40=U$3,$M40,"") | V40: =+"Refer to FS6, Status: "& +M61 -> Refer to FS6, Status: R
...

Sheet TEMP
A1: RQMT # | B1: Priority | C1: CVT | D1: CVT Script Title | E1: Test Status | F1: IP-1 Pass Date | G1: IP-2 Pass Date | H1: IP-3 Pass Date | I1: CVT Status FYDP | M1: CVT Status (NT,A,P,F) | N1: DR # | V1: Comment | W1: CR #, if applicable
J2: Critical | K2: Major | L2: Minor | N2: 1 | O2: 2 | P2: 3 | Q2: 4 | R2: 5 | S2: Critical | T2: Major | U2: Minor
A3: FRM 4.3. FRM 4.27 | B3: Major | C3: NAV1 | D3: Select a Data Call | E3: Ready | I3: P | J3: =IF($B3=J$2,$I3,"") | K3: =IF($B3=K$2,$I3,"") -> P | L3: =IF($B3=L$2,$I3,"") | M3: P | S3: =IF($B3=S$2,$M3,"") | T3: =IF($B3=T$2,$M3,"") -> P | U3: =IF($B3=U$2,$M3,"")
A4: N/A | B4: Major | C4: NAV2 | D4: FRM Sections: (Navigate to Inputs, Data Sheet Views, Reports) | E4: Ready | I4: P | J4: =IF($B4=J$2,$I4,"") | K4: =IF($B4=K$2,$I4,"") -> P | L4: =IF($B4=L$2,$I4,"") | M4: P | S4: =IF($B4=S$2,$M4,"") | T4: =IF($B4=T$2,$M4,"") -> P | U4: =IF($B4=U$2,$M4,"") | V4: CVT Updates Applied
A5: FM 5.1-5.2 | B5: Major | C5: NAV3 | D5: Navigate to "Target Maintenance" | E5: Ready | I5: P | J5: =IF($B5=J$2,$I5,"") | K5: =IF($B5=K$2,$I5,"") -> P | L5: =IF($B5=L$2,$I5,"") | M5: P | S5: =IF($B5=S$2,$M5,"") | T5: =IF($B5=T$2,$M5,"") -> P | U5: =IF($B5=U$2,$M5,"") | V5: CVT Updates Applied
A6: FRM 6.1-6.2 | B6: Critical | C6: NAV4 | D6: Navigate to "QM Funds Spread" | E6: Ready | I6: P | J6: =IF($B6=J$2,$I6,"") -> P | K6: =IF($B6=K$2,$I6,"") | L6: =IF($B6=L$2,$I6,"") | M6: P | N6: X | R6: X | S6: =IF($B6=S$2,$M6,"") -> P | T6: =IF($B6=T$2,$M6,"") | U6: =IF($B6=U$2,$M6,"") | V6: CVT Updates Applied
A7: FRM 7.1 | B7: Critical | C7: NAV5 | D7: RQMT ADJUSTMENT: QM (Quick Maintenance) Requirement: Access Grid | E7: Ready | I7: P | J7: =IF($B7=J$2,$I7,"") -> P | K7: =IF($B7=K$2,$I7,"") | L7: =IF($B7=L$2,$I7,"") | M7: P | N7: X | S7: =IF($B7=S$2,$M7,"") -> P | T7: =IF($B7=T$2,$M7,"") | U7: =IF($B7=U$2,$M7,"")
A8: - | B8: Critical | C8: UM1 | D8: FRM Basics: Register for FRM | E8: Ready | I8: N/A | J8: =IF($B8=J$2,$I8,"") -> N/A | K8: =IF($B8=K$2,$I8,"") | L8: =IF($B8=L$2,$I8,"") | M8: N/A | S8: =IF($B8=S$2,$M8,"") -> N/A | T8: =IF($B8=T$2,$M8,"") | U8: =IF($B8=U$2,$M8,"") | V8: Recommend removing from this test agenda
A9: FRM 1.1 - 1.5 | B9: Critical | C9: UM2 | D9: Activate User (Generic) | E9: Ready | I9: P | J9: =IF($B9=J$2,$I9,"") -> P | K9: =IF($B9=K$2,$I9,"") | L9: =IF($B9=L$2,$I9,"") | M9: P | S9: =IF($B9=S$2,$M9,"") -> P | T9: =IF($B9=T$2,$M9,"") | U9: =IF($B9=U$2,$M9,"")
A10: FRM 1.1 - 1.5 | B10: Critical | C10: UM3 | D10: Confirm Activated User | E10: Ready | I10: P | J10: =IF($B10=J$2,$I10,"") -> P | K10: =IF($B10=K$2,$I10,"") | L10: =IF($B10=L$2,$I10,"") | M10: P | S10: =IF($B10=S$2,$M10,"") -> P | T10: =IF($B10=T$2,$M10,"") | U10: =IF($B10=U$2,$M10,"")
A11: FRM 1.1 - 1.5 | B11: Critical | C11: UM4 | D11: Confirm Filter | E11: Ready | I11: R | J11: =IF($B11=J$2,$I11,"") -> R | K11: =IF($B11=K$2,$I11,"") | L11: =IF($B11=L$2,$I11,"") | M11: R | S11: =IF($B11=S$2,$M11,"") -> R | T11: =IF($B11=T$2,$M11,"") | U11: =IF($B11=U$2,$M11,"") | V11: Change to be made to add PEC
A12: FRM 1.1 - 1.5 | B12: Major | C12: UM5 | D12: Confirm User Management Roles | E12: Ready | I12: P | J12: =IF($B12=J$2,$I12,"") | K12: =IF($B12=K$2,$I12,"") -> P | L12: =IF($B12=L$2,$I12,"") | M12: P | S12: =IF($B12=S$2,$M12,"") | T12: =IF($B12=T$2,$M12,"") -> P | U12: =IF($B12=U$2,$M12,"")
A13: 4.8, 1.1, 1.2 | B13: Critical | C13: DCROLE1 | D13: Manage Roles and Responsibility | E13: Ready | I13: P | J13: =IF($B13=J$2,$I13,"") -> P | K13: =IF($B13=K$2,$I13,"") | L13: =IF($B13=L$2,$I13,"") | M13: P | S13: =IF($B13=S$2,$M13,"") -> P | T13: =IF($B13=T$2,$M13,"") | U13: =IF($B13=U$2,$M13,"")
A14: 4.8 | B14: Major | C14: DCROLE2 | D14: Review Roles and Responsibilities by Users | E14: Ready | I14: P | J14: =IF($B14=J$2,$I14,"") | K14: =IF($B14=K$2,$I14,"") -> P | L14: =IF($B14=L$2,$I14,"") | M14: P | S14: =IF($B14=S$2,$M14,"") | T14: =IF($B14=T$2,$M14,"") -> P | U14: =IF($B14=U$2,$M14,"")
A15: 4.8, 4.12 | B15: Major | C15: DCROLE3 | D15: Review Roles and Responsibilities by Affiliation | E15: Ready | I15: P | J15: =IF($B15=J$2,$I15,"") | K15: =IF($B15=K$2,$I15,"") -> P | L15: =IF($B15=L$2,$I15,"") | M15: P | S15: =IF($B15=S$2,$M15,"") | T15: =IF($B15=T$2,$M15,"") -> P | U15: =IF($B15=U$2,$M15,"")
A16: 2.3 | B16: Critical | C16: DCROLE4 | D16: Search for User | E16: Ready | I16: P | J16: =IF($B16=J$2,$I16,"") -> P | K16: =IF($B16=K$2,$I16,"") | L16: =IF($B16=L$2,$I16,"") | M16: P | S16: =IF($B16=S$2,$M16,"") -> P | T16: =IF($B16=T$2,$M16,"") | U16: =IF($B16=U$2,$M16,"")
A17: 4.4, 4.8 | B17: Major | C17: DCROLE5 | D17: Mass Change User Roles - Add Roles | E17: Ready | I17: P | J17: =IF($B17=J$2,$I17,"") | K17: =IF($B17=K$2,$I17,"") -> P | L17: =IF($B17=L$2,$I17,"") | M17: P | S17: =IF($B17=S$2,$M17,"") | T17: =IF($B17=T$2,$M17,"") -> P | U17: =IF($B17=U$2,$M17,"")
A18: 4.4, 4.8 | B18: Major | C18: DCROLE6 | D18: Mass Change User Roles - Remove Roles | E18: Ready | I18: P | J18: =IF($B18=J$2,$I18,"") | K18: =IF($B18=K$2,$I18,"") -> P | L18: =IF($B18=L$2,$I18,"") | M18: P | S18: =IF($B18=S$2,$M18,"") | T18: =IF($B18=T$2,$M18,"") -> P | U18: =IF($B18=U$2,$M18,"")
A19: 4.9, 4.10 | B19: Critical | C19: DC1 | D19: Create Execution Data Call | E19: unpredictable results | I19: Data call | J19: =IF($B19=J$2,$I19,"") -> Data call | K19: =IF($B19=K$2,$I19,"") | L19: =IF($B19=L$2,$I19,"") | M19: NT | S19: =IF($B19=S$2,$M19,"") -> NT | T19: =IF($B19=T$2,$M19,"") | U19: =IF($B19=U$2,$M19,"")
A20: 4.9, 4.10 | B20: Critical | C20: DC2 | D20: Create FYDP FRM Data Call | E20: unpredictable results | I20: Data call | J20: =IF($B20=J$2,$I20,"") -> Data call | K20: =IF($B20=K$2,$I20,"") | L20: =IF($B20=L$2,$I20,"") | M20: NT | S20: =IF($B20=S$2,$M20,"") -> NT | T20: =IF($B20=T$2,$M20,"") | U20: =IF($B20=U$2,$M20,"")
A21: FRM 4.12, 4.15-4.17 | B21: Critical | C21: DC3 | D21: Review Data Call Options | E21: Ready | I21: R | J21: =IF($B21=J$2,$I21,"") -> R | K21: =IF($B21=K$2,$I21,"") | L21: =IF($B21=L$2,$I21,"") | M21: R | S21: =IF($B21=S$2,$M21,"") -> R | T21: =IF($B21=T$2,$M21,"") | U21: =IF($B21=U$2,$M21,"") | V21: CVT updates applied
A22: FRM 4.11 | B22: Critical | C22: DC4 | D22: Add Years to Data Call | E22: Ready | I22: Data call | J22: =IF($B22=J$2,$I22,"") -> Data call | K22: =IF($B22=K$2,$I22,"") | L22: =IF($B22=L$2,$I22,"") | M22: NT | S22: =IF($B22=S$2,$M22,"") -> NT | T22: =IF($B22=T$2,$M22,"") | U22: =IF($B22=U$2,$M22,"")
A23: FRM 7.6, 4.2 | B23: Critical | C23: DC5 | D23: Audit Requirement | E23: Ready | I23: Data call | J23: =IF($B23=J$2,$I23,"") -> Data call | K23: =IF($B23=K$2,$I23,"") | L23: =IF($B23=L$2,$I23,"") | M23: NT | S23: =IF($B23=S$2,$M23,"") -> NT | T23: =IF($B23=T$2,$M23,"") | U23: =IF($B23=U$2,$M23,"")
A24: FRM 5.6 | B24: Major | C24: DC6 | D24: Audit Target | E24: Ready | I24: Data call | J24: =IF($B24=J$2,$I24,"") | K24: =IF($B24=K$2,$I24,"") -> Data call | L24: =IF($B24=L$2,$I24,"") | M24: NT | S24: =IF($B24=S$2,$M24,"") | T24: =IF($B24=T$2,$M24,"") -> NT | U24: =IF($B24=U$2,$M24,"")
A25: FRM 6.8, FRM 6.9 | B25: Major | C25: DC7 | D25: Audit Funds Spread | E25: Ready | I25: Data call | J25: =IF($B25=J$2,$I25,"") | K25: =IF($B25=K$2,$I25,"") -> Data call | L25: =IF($B25=L$2,$I25,"") | M25: NT | S25: =IF($B25=S$2,$M25,"") | T25: =IF($B25=T$2,$M25,"") -> NT | U25: =IF($B25=U$2,$M25,"")
A26: Missing | B26: Minor | C26: DC8 | D26: Delete Data Call | E26: Ready | I26: Data call | J26: =IF($B26=J$2,$I26,"") | K26: =IF($B26=K$2,$I26,"") | L26: =IF($B26=L$2,$I26,"") -> Data call | M26: NT | S26: =IF($B26=S$2,$M26,"") | T26: =IF($B26=T$2,$M26,"") | U26: =IF($B26=U$2,$M26,"") -> NT
A27: 4.8,4.4 | B27: Major | C27: DC9 | D27: Certify Data Call Ready for File Maintenance | E27: Ready | I27: Data call | J27: =IF($B27=J$2,$I27,"") | K27: =IF($B27=K$2,$I27,"") -> Data call | L27: =IF($B27=L$2,$I27,"") | M27: NT | S27: =IF($B27=S$2,$M27,"") | T27: =IF($B27=T$2,$M27,"") -> NT | U27: =IF($B27=U$2,$M27,"")
A28: 4.4, 5.12, 6.11 | B28: Critical | C28: DC10 | D28: Close Data Call | E28: Ready | I28: Data call | J28: =IF($B28=J$2,$I28,"") -> Data call | K28: =IF($B28=K$2,$I28,"") | L28: =IF($B28=L$2,$I28,"") | M28: NT | S28: =IF($B28=S$2,$M28,"") -> NT | T28: =IF($B28=T$2,$M28,"") | U28: =IF($B28=U$2,$M28,"")
A29: FRM 4.4, 4.13, 6.3 | B29: Major | C29: MassDC1 | D29: Overlay DC Funding | E29: DUPLICATE | I29: DUP | J29: =IF($B29=J$2,$I29,"") | K29: =IF($B29=K$2,$I29,"") -> DUP | L29: =IF($B29=L$2,$I29,"") | M29: DUP | S29: =IF($B29=S$2,$M29,"") | T29: =IF($B29=T$2,$M29,"") -> DUP | U29: =IF($B29=U$2,$M29,"") | V29: =+"Refer to FS9, Status: "& M56 -> Refer to FS9, Status: P
A30: FRM 4.4, 4.13 | B30: Major | C30: MassDC2 | D30: Mass Change: Update Status | E30: Ready | I30: NA | J30: =IF($B30=J$2,$I30,"") | K30: =IF($B30=K$2,$I30,"") -> NA | L30: =IF($B30=L$2,$I30,"") | M30: NA | S30: =IF($B30=S$2,$M30,"") | T30: =IF($B30=T$2,$M30,"") -> NA | U30: =IF($B30=U$2,$M30,"")
A31: FRM 4.4, 4.13, 6.3 | B31: Major | C31: MassDC3 | D31: Mass Change: 70% Spread to Target by Priority | E31: DUPLICATE | I31: DUP | J31: =IF($B31=J$2,$I31,"") | K31: =IF($B31=K$2,$I31,"") -> DUP | L31: =IF($B31=L$2,$I31,"") | M31: DUP | S31: =IF($B31=S$2,$M31,"") | T31: =IF($B31=T$2,$M31,"") -> DUP | U31: =IF($B31=U$2,$M31,"") | V31: =+"Refer to FS3, Status: "& +M50 -> Refer to FS3, Status: R
A32: FRM 4.4, 4.13, 6.3 | B32: Critical | C32: MassDC4 | D32: Mass Change: Fully Fund to Target | E32: DUPLICATE | I32: DUP | J32: =IF($B32=J$2,$I32,"") -> DUP | K32: =IF($B32=K$2,$I32,"") | L32: =IF($B32=L$2,$I32,"") | M32: DUP | S32: =IF($B32=S$2,$M32,"") -> DUP | T32: =IF($B32=T$2,$M32,"") | U32: =IF($B32=U$2,$M32,"") | V32: =+"Refer to FS4, Status: "& +M51 -> Refer to FS4, Status: P
A33: FRM 4.4, 4.13, 6.3 | B33: Major | C33: MassDC5 | D33: Mass Change: OP30 Spread; next 70% Spread to Target by Priority | E33: DUPLICATE | I33: DUP | J33: =IF($B33=J$2,$I33,"") | K33: =IF($B33=K$2,$I33,"") -> DUP | L33: =IF($B33=L$2,$I33,"") | M33: DUP | S33: =IF($B33=S$2,$M33,"") | T33: =IF($B33=T$2,$M33,"") -> DUP | U33: =IF($B33=U$2,$M33,"") | V33: =+"Refer to FS5, Status: "& +M52 -> Refer to FS5, Status: R
A34: FRM 4.4, 4.13, 6.3 | B34: Major | C34: MassDC6 | D34: Mass Change: Fully Fund | E34: DUPLICATE | I34: DUP | J34: =IF($B34=J$2,$I34,"") | K34: =IF($B34=K$2,$I34,"") -> DUP | L34: =IF($B34=L$2,$I34,"") | M34: DUP | S34: =IF($B34=S$2,$M34,"") | T34: =IF($B34=T$2,$M34,"") -> DUP | U34: =IF($B34=U$2,$M34,"") | V34: =+"Refer to FS6, Status: "& +M53 -> Refer to FS6, Status: R
A35: FRM 4.4, 4.13, 6.3 | B35: Major | C35: MassDC7 | D35: Mass Change: Unfund | E35: DUPLICATE | I35: DUP | J35: =IF($B35=J$2,$I35,"") | K35: =IF($B35=K$2,$I35,"") -> DUP | L35: =IF($B35=L$2,$I35,"") | M35: DUP | S35: =IF($B35=S$2,$M35,"") | T35: =IF($B35=T$2,$M35,"") -> DUP | U35: =IF($B35=U$2,$M35,"") | V35: =+"Refer to FS7, Status: "& +M54 -> Refer to FS7, Status: P
A36: FRM 4.4, 4.13,5.2 | B36: Major | C36: MassDC8 | D36: Overlay Target | E36: DUPLICATE | I36: DUP | J36: =IF($B36=J$2,$I36,"") | K36: =IF($B36=K$2,$I36,"") -> DUP | L36: =IF($B36=L$2,$I36,"") | M36: DUP | S36: =IF($B36=S$2,$M36,"") | T36: =IF($B36=T$2,$M36,"") -> DUP | U36: =IF($B36=U$2,$M36,"")
A37: FRM 4.4, 4.13,5.2 | B37: Major | C37: MassDC9 | D37: Copy Target to Target | E37: DUPLICATE | I37: DUP | J37: =IF($B37=J$2,$I37,"") | K37: =IF($B37=K$2,$I37,"") -> DUP | L37: =IF($B37=L$2,$I37,"") | M37: DUP | S37: =IF($B37=S$2,$M37,"") | T37: =IF($B37=T$2,$M37,"") -> DUP | U37: =IF($B37=U$2,$M37,"") | V37: Refer to TGT2, Status:
A38: FRM 4.4, 4.13,5.2 | B38: Major | C38: MassDC10 | D38: Get (Append) Target | E38: DUPLICATE | I38: DUP | J38: =IF($B38=J$2,$I38,"") | K38: =IF($B38=K$2,$I38,"") -> DUP | L38: =IF($B38=L$2,$I38,"") | M38: DUP | S38: =IF($B38=S$2,$M38,"") | T38: =IF($B38=T$2,$M38,"") -> DUP | U38: =IF($B38=U$2,$M38,"")
A39: 5.2, 5.13, 4.4 | B39: Major | C39: TGT2 | D39: DATA MAINTENANCE: Mass Change: Copy Target to Target | E39: Ready | I39: P | J39: =IF($B39=J$2,$I39,"") | K39: =IF($B39=K$2,$I39,"") -> P | L39: =IF($B39=L$2,$I39,"") | M39: P | S39: =IF($B39=S$2,$M39,"") | T39: =IF($B39=T$2,$M39,"") -> P | U39: =IF($B39=U$2,$M39,"")
A40: 5.2, 5.13, 4.4 | B40: Major | C40: TGT3 | D40: Target Maintenance: Mass Change: Zero out all Targets | E40: Ready | I40: P | J40: =IF($B40=J$2,$I40,"") | K40: =IF($B40=K$2,$I40,"") -> P | L40: =IF($B40=L$2,$I40,"") | M40: P | S40: =IF($B40=S$2,$M40,"") | T40: =IF($B40=T$2,$M40,"") -> P | U40: =IF($B40=U$2,$M40,"")
...

Sheet Priority
A2: RQMT # | B2: Description | C2: Priority | D2: CVT # | E2: CVT | F2: CVT | G2: =+'CVT Master List'!C5 -> NAV1 | H2: =+'CVT Master List'!C6 -> NAV2 | I2: =+'CVT Master List'!C7 -> NAV3 | J2: =+'CVT Master List'!C8 -> NAV4 | K2: =+'CVT Master List'!C9 -> NAV5 | L2: User Mgmt | M2: =+'CVT Master List'!C11 -> UM1 | N2: =+'CVT Master List'!C12 -> UM2 | O2: =+'CVT Master List'!C13 -> UM3 | P2: =+'CVT Master List'!C14 -> UM4 | Q2: =+'CVT Master List'!C15 -> UM5 | R2: DC Role | S2: =+'CVT Master List'!C17 -> DCROLE1 | T2: =+'CVT Master List'!C18 -> DCROLE2 | U2: =+'CVT Master List'!C19 -> DCROLE3 | V2: =+'CVT Master List'!C20 -> DCROLE4 | W2: =+'CVT Master List'!C21 -> DCROLE5 | X2: =+'CVT Master List'!C22 -> DCROLE6 | Y2: DC Mgmt | Z2: =+'CVT Master List'!C24 -> DC1 | AA2: =+'CVT Master List'!C25 -> DC2 | AB2: =+'CVT Master List'!C26 -> DC3 | AC2: =+'CVT Master List'!C27 -> DC4 | AD2: =+'CVT Master List'!C28 -> DC5 | AE2: =+'CVT Master List'!C29 -> DC6 | AF2: =+'CVT Master List'!C30 -> DC7 | AG2: =+'CVT Master List'!C31 -> DC8 | AH2: DC9 | AI2: DC10 | AJ2: Mass chng | AK2: =+'CVT Master List'!C35 -> MassDC1 | AL2: =+'CVT Master List'!C36 -> MassDC2 | AM2: =+'CVT Master List'!C37 -> MassDC3 | AN2: =+'CVT Master List'!C38 -> MassDC4 | AO2: =+'CVT Master List'!C39 -> MassDC5 | AP2: =+'CVT Master List'!C40 -> MassDC6 | AQ2: =+'CVT Master List'!C41 -> MassDC7 | AR2: =+'CVT Master List'!C42 -> MassDC8 | AS2: =+'CVT Master List'!C43 -> MassDC9 | AT2: =+'CVT Master List'!C44 -> MassDC10 | AU2: TGT | AV2: =+'CVT Master List'!#REF! -> #REF! | AW2: =+'CVT Master List'!C46 -> TGT2 | AX2: =+'CVT Master List'!C47 -> TGT3 | AY2: =+'CVT Master List'!C48 -> TGT4 | AZ2: =+'CVT Master List'!C49 -> TGT5 | BA2: =+'CVT Master List'!C50 -> TGT6 | BB2: =+'CVT Master List'!C51 -> TGT7 | BC2: F S | BD2: =+'CVT Master List'!C58 -> FS3 | BE2: =+'CVT Master List'!C59 -> FS4 | BF2: =+'CVT Master List'!C60 -> FS5 | BG2: =+'CVT Master List'!C61 -> FS6 | BH2: =+'CVT Master List'!C62 -> FS7 | BI2: =+'CVT Master List'!C63 -> FS8 | BJ2: =+'CVT Master List'!C64 -> FS9 | BK2: =+'CVT Master List'!C65 -> FS10 | BL2: =+'CVT Master List'!#REF! -> #REF! | BM2: RPT | BN2: =+'CVT Master List'!C67 -> RPT1 | BO2: =+'CVT Master List'!C68 -> RPT2 | BP2: =+'CVT Master List'!C69 -> RPT3 | BQ2: =+'CVT Master List'!C71 -> RPT5 | BR2: =+'CVT Master List'!C72 -> RPT6 | BS2: =+'CVT Master List'!C73 -> RPT7 | BT2: =+'CVT Master List'!C74 -> RPT8 | BU2: Tools | BV2: =+'CVT Master List'!C79 -> TOOLS1 | BW2: =+'CVT Master List'!C80 -> TOOLS2 | BX2: =+'CVT Master List'!C81 -> TOOLS3 | BY2: =+'CVT Master List'!C82 -> TOOLS4 | BZ2: =+'CVT Master List'!C83 -> TOOLS 5 | CA2: =+'CVT Master List'!C84 -> TOOLS6 | CB2: RQMT | CC2: =+'CVT Master List'!C87 -> RQMT1 | CD2: =+'CVT Master List'!C88 -> RQMT2 | CE2: =+'CVT Master List'!C89 -> 0 | CF2: =+'CVT Master List'!C92 -> OBL2
E3: STATUS | F3: DETAILS | G3: =IF(COUNTIFS(G5:G80,"CRITICAL")>0,"Critical",IF(COUNTIFS(G5:G80,"Major")>0,"Major",IF(COUNTIFS(G5:G80,"Minor")>0,"Minor","UNK"))) -> UNK | H3: =IF(COUNTIFS(H5:H80,"CRITICAL")>0,"Critical",IF(COUNTIFS(H5:H80,"Major")>0,"Major",IF(COUNTIFS(H5:H80,"Minor")>0,"Minor","UNK"))) -> UNK | I3: =IF(COUNTIFS(I5:I80,"CRITICAL")>0,"Critical",IF(COUNTIFS(I5:I80,"Major")>0,"Major",IF(COUNTIFS(I5:I80,"Minor")>0,"Minor","UNK"))) -> UNK | J3: =IF(COUNTIFS(J5:J80,"CRITICAL")>0,"Critical",IF(COUNTIFS(J5:J80,"Major")>0,"Major",IF(COUNTIFS(J5:J80,"Minor")>0,"Minor","UNK"))) -> UNK | K3: =IF(COUNTIFS(K5:K80,"CRITICAL")>0,"Critical",IF(COUNTIFS(K5:K80,"Major")>0,"Major",IF(COUNTIFS(K5:K80,"Minor")>0,"Minor","UNK"))) -> UNK | M3: =IF(COUNTIFS(M5:M80,"CRITICAL")>0,"Critical",IF(COUNTIFS(M5:M80,"Major")>0,"Major",IF(COUNTIFS(M5:M80,"Minor")>0,"Minor","UNK"))) -> UNK | N3: =IF(COUNTIFS(N5:N80,"CRITICAL")>0,"Critical",IF(COUNTIFS(N5:N80,"Major")>0,"Major",IF(COUNTIFS(N5:N80,"Minor")>0,"Minor","UNK"))) -> UNK | O3: =IF(COUNTIFS(O5:O80,"CRITICAL")>0,"Critical",IF(COUNTIFS(O5:O80,"Major")>0,"Major",IF(COUNTIFS(O5:O80,"Minor")>0,"Minor","UNK"))) -> UNK | P3: =IF(COUNTIFS(P5:P80,"CRITICAL")>0,"Critical",IF(COUNTIFS(P5:P80,"Major")>0,"Major",IF(COUNTIFS(P5:P80,"Minor")>0,"Minor","UNK"))) -> UNK | Q3: =IF(COUNTIFS(Q5:Q80,"CRITICAL")>0,"Critical",IF(COUNTIFS(Q5:Q80,"Major")>0,"Major",IF(COUNTIFS(Q5:Q80,"Minor")>0,"Minor","UNK"))) -> UNK | S3: =IF(COUNTIFS(S5:S80,"CRITICAL")>0,"Critical",IF(COUNTIFS(S5:S80,"Major")>0,"Major",IF(COUNTIFS(S5:S80,"Minor")>0,"Minor","UNK"))) -> UNK | T3: =IF(COUNTIFS(T5:T80,"CRITICAL")>0,"Critical",IF(COUNTIFS(T5:T80,"Major")>0,"Major",IF(COUNTIFS(T5:T80,"Minor")>0,"Minor","UNK"))) -> UNK | U3: =IF(COUNTIFS(U5:U80,"CRITICAL")>0,"Critical",IF(COUNTIFS(U5:U80,"Major")>0,"Major",IF(COUNTIFS(U5:U80,"Minor")>0,"Minor","UNK"))) -> UNK | V3: =IF(COUNTIFS(V5:V80,"CRITICAL")>0,"Critical",IF(COUNTIFS(V5:V80,"Major")>0,"Major",IF(COUNTIFS(V5:V80,"Minor")>0,"Minor","UNK"))) -> UNK | W3: =IF(COUNTIFS(W5:W80,"CRITICAL")>0,"Critical",IF(COUNTIFS(W5:W80,"Major")>0,"Major",IF(COUNTIFS(W5:W80,"Minor")>0,"Minor","UNK"))) -> UNK | X3: =IF(COUNTIFS(X5:X80,"CRITICAL")>0,"Critical",IF(COUNTIFS(X5:X80,"Major")>0,"Major",IF(COUNTIFS(X5:X80,"Minor")>0,"Minor","UNK"))) -> UNK | Z3: =IF(COUNTIFS(Z5:Z80,"CRITICAL")>0,"Critical",IF(COUNTIFS(Z5:Z80,"Major")>0,"Major",IF(COUNTIFS(Z5:Z80,"Minor")>0,"Minor","UNK"))) -> UNK | AA3: =IF(COUNTIFS(AA5:AA80,"CRITICAL")>0,"Critical",IF(COUNTIFS(AA5:AA80,"Major")>0,"Major",IF(COUNTIFS(AA5:AA80,"Minor")>0,"Minor","UNK"))) -> UNK | AB3: =IF(COUNTIFS(AB5:AB80,"CRITICAL")>0,"Critical",IF(COUNTIFS(AB5:AB80,"Major")>0,"Major",IF(COUNTIFS(AB5:AB80,"Minor")>0,"Minor","UNK"))) -> UNK | AC3: =IF(COUNTIFS(AC5:AC80,"CRITICAL")>0,"Critical",IF(COUNTIFS(AC5:AC80,"Major")>0,"Major",IF(COUNTIFS(AC5:AC80,"Minor")>0,"Minor","UNK"))) -> UNK | AD3: =IF(COUNTIFS(AD5:AD80,"CRITICAL")>0,"Critical",IF(COUNTIFS(AD5:AD80,"Major")>0,"Major",IF(COUNTIFS(AD5:AD80,"Minor")>0,"Minor","UNK"))) -> UNK | AE3: =IF(COUNTIFS(AE5:AE80,"CRITICAL")>0,"Critical",IF(COUNTIFS(AE5:AE80,"Major")>0,"Major",IF(COUNTIFS(AE5:AE80,"Minor")>0,"Minor","UNK"))) -> UNK | AF3: =IF(COUNTIFS(AF5:AF80,"CRITICAL")>0,"Critical",IF(COUNTIFS(AF5:AF80,"Major")>0,"Major",IF(COUNTIFS(AF5:AF80,"Minor")>0,"Minor","UNK"))) -> UNK | AG3: =IF(COUNTIFS(AG5:AG80,"CRITICAL")>0,"Critical",IF(COUNTIFS(AG5:AG80,"Major")>0,"Major",IF(COUNTIFS(AG5:AG80,"Minor")>0,"Minor","UNK"))) -> UNK | ... AI3: =IF(COUNTIFS(AI5:AI80,"CRITICAL")>0,"Critical",IF(COUNTIFS(AI5:AI80,"Major")>0,"Major",IF(COUNTIFS(AI5:AI80,"Minor")>0,"Minor","UNK"))) -> UNK | AK3: =IF(COUNTIFS(AK5:AK80,"CRITICAL")>0,"Critical",IF(COUNTIFS(AK5:AK80,"Major")>0,"Major",IF(COUNTIFS(AK5:AK80,"Minor")>0,"Minor","UNK"))) -> UNK | AL3: =IF(COUNTIFS(AL5:AL80,"CRITICAL")>0,"Critical",IF(COUNTIFS(AL5:AL80,"Major")>0,"Major",IF(COUNTIFS(AL5:AL80,"Minor")>0,"Minor","UNK"))) -> UNK | AM3: =IF(COUNTIFS(AM5:AM80,"CRITICAL")>0,"Critical",IF(COUNTIFS(AM5:AM80,"Major")>0,"Major",IF(COUNTIFS(AM5:AM80,"Minor")>0,"Minor","UNK"))) -> UNK | AN3: =IF(COUNTIFS(AN5:AN80,"CRITICAL")>0,"Critical",IF(COUNTIFS(AN5:AN80,"Major")>0,"Major",IF(COUNTIFS(AN5:AN80,"Minor")>0,"Minor","UNK"))) -> UNK | AO3: =IF(COUNTIFS(AO5:AO80,"CRITICAL")>0,"Critical",IF(COUNTIFS(AO5:AO80,"Major")>0,"Major",IF(COUNTIFS(AO5:AO80,"Minor")>0,"Minor","UNK"))) -> UNK | AP3: =IF(COUNTIFS(AP5:AP80,"CRITICAL")>0,"Critical",IF(COUNTIFS(AP5:AP80,"Major")>0,"Major",IF(COUNTIFS(AP5:AP80,"Minor")>0,"Minor","UNK"))) -> UNK | AQ3: =IF(COUNTIFS(AQ5:AQ80,"CRITICAL")>0,"Critical",IF(COUNTIFS(AQ5:AQ80,"Major")>0,"Major",IF(COUNTIFS(AQ5:AQ80,"Minor")>0,"Minor","UNK"))) -> UNK | AR3: =IF(COUNTIFS(AR5:AR80,"CRITICAL")>0,"Critical",IF(COUNTIFS(AR5:AR80,"Major")>0,"Major",IF(COUNTIFS(AR5:AR80,"Minor")>0,"Minor","UNK"))) -> UNK | ... AT3: =IF(COUNTIFS(AT5:AT80,"CRITICAL")>0,"Critical",IF(COUNTIFS(AT5:AT80,"Major")>0,"Major",IF(COUNTIFS(AT5:AT80,"Minor")>0,"Minor","UNK"))) -> UNK | AV3: =IF(COUNTIFS(AV5:AV80,"CRITICAL")>0,"Critical",IF(COUNTIFS(AV5:AV80,"Major")>0,"Major",IF(COUNTIFS(AV5:AV80,"Minor")>0,"Minor","UNK"))) -> UNK | AW3: =IF(COUNTIFS(AW5:AW80,"CRITICAL")>0,"Critical",IF(COUNTIFS(AW5:AW80,"Major")>0,"Major",IF(COUNTIFS(AW5:AW80,"Minor")>0,"Minor","UNK"))) -> UNK | AX3: =IF(COUNTIFS(AX5:AX80,"CRITICAL")>0,"Critical",IF(COUNTIFS(AX5:AX80,"Major")>0,"Major",IF(COUNTIFS(AX5:AX80,"Minor")>0,"Minor","UNK"))) -> UNK | AY3: =IF(COUNTIFS(AY5:AY80,"CRITICAL")>0,"Critical",IF(COUNTIFS(AY5:AY80,"Major")>0,"Major",IF(COUNTIFS(AY5:AY80,"Minor")>0,"Minor","UNK"))) -> UNK | AZ3: =IF(COUNTIFS(AZ5:AZ80,"CRITICAL")>0,"Critical",IF(COUNTIFS(AZ5:AZ80,"Major")>0,"Major",IF(COUNTIFS(AZ5:AZ80,"Minor")>0,"Minor","UNK"))) -> UNK | BA3: =IF(COUNTIFS(BA5:BA80,"CRITICAL")>0,"Critical",IF(COUNTIFS(BA5:BA80,"Major")>0,"Major",IF(COUNTIFS(BA5:BA80,"Minor")>0,"Minor","UNK"))) -> UNK | BB3: =IF(COUNTIFS(BB5:BB80,"CRITICAL")>0,"Critical",IF(COUNTIFS(BB5:BB80,"Major")>0,"Major",IF(COUNTIFS(BB5:BB80,"Minor")>0,"Minor","UNK"))) -> UNK | BD3: =IF(COUNTIFS(BD5:BD80,"CRITICAL")>0,"Critical",IF(COUNTIFS(BD5:BD80,"Major")>0,"Major",IF(COUNTIFS(BD5:BD80,"Minor")>0,"Minor","UNK"))) -> UNK | BE3: =IF(COUNTIFS(BE5:BE80,"CRITICAL")>0,"Critical",IF(COUNTIFS(BE5:BE80,"Major")>0,"Major",IF(COUNTIFS(BE5:BE80,"Minor")>0,"Minor","UNK"))) -> UNK | BF3: =IF(COUNTIFS(BF5:BF80,"CRITICAL")>0,"Critical",IF(COUNTIFS(BF5:BF80,"Major")>0,"Major",IF(COUNTIFS(BF5:BF80,"Minor")>0,"Minor","UNK"))) -> UNK | BG3: =IF(COUNTIFS(BG5:BG80,"CRITICAL")>0,"Critical",IF(COUNTIFS(BG5:BG80,"Major")>0,"Major",IF(COUNTIFS(BG5:BG80,"Minor")>0,"Minor","UNK"))) -> UNK | BH3: =IF(COUNTIFS(BH5:BH80,"CRITICAL")>0,"Critical",IF(COUNTIFS(BH5:BH80,"Major")>0,"Major",IF(COUNTIFS(BH5:BH80,"Minor")>0,"Minor","UNK"))) -> UNK | BI3: =IF(COUNTIFS(BI5:BI80,"CRITICAL")>0,"Critical",IF(COUNTIFS(BI5:BI80,"Major")>0,"Major",IF(COUNTIFS(BI5:BI80,"Minor")>0,"Minor","UNK"))) -> UNK | BJ3: =IF(COUNTIFS(BJ5:BJ80,"CRITICAL")>0,"Critical",IF(COUNTIFS(BJ5:BJ80,"Major")>0,"Major",IF(COUNTIFS(BJ5:BJ80,"Minor")>0,"Minor","UNK"))) -> UNK | BK3: =IF(COUNTIFS(BK5:BK80,"CRITICAL")>0,"Critical",IF(COUNTIFS(BK5:BK80,"Major")>0,"Major",IF(COUNTIFS(BK5:BK80,"Minor")>0,"Minor","UNK"))) -> UNK | BL3: =IF(COUNTIFS(BL5:BL80,"CRITICAL")>0,"Critical",IF(COUNTIFS(BL5:BL80,"Major")>0,"Major",IF(COUNTIFS(BL5:BL80,"Minor")>0,"Minor","UNK"))) -> UNK | BN3: =IF(COUNTIFS(BN5:BN80,"CRITICAL")>0,"Critical",IF(COUNTIFS(BN5:BN80,"Major")>0,"Major",IF(COUNTIFS(BN5:BN80,"Minor")>0,"Minor","UNK"))) -> UNK | BO3: =IF(COUNTIFS(BO5:BO80,"CRITICAL")>0,"Critical",IF(COUNTIFS(BO5:BO80,"Major")>0,"Major",IF(COUNTIFS(BO5:BO80,"Minor")>0,"Minor","UNK"))) -> UNK | BP3: =IF(COUNTIFS(BP5:BP80,"CRITICAL")>0,"Critical",IF(COUNTIFS(BP5:BP80,"Major")>0,"Major",IF(COUNTIFS(BP5:BP80,"Minor")>0,"Minor","UNK"))) -> UNK | BQ3: =IF(COUNTIFS(BQ5:BQ80,"CRITICAL")>0,"Critical",IF(COUNTIFS(BQ5:BQ80,"Major")>0,"Major",IF(COUNTIFS(BQ5:BQ80,"Minor")>0,"Minor","UNK"))) -> UNK | BR3: =IF(COUNTIFS(BR5:BR80,"CRITICAL")>0,"Critical",IF(COUNTIFS(BR5:BR80,"Major")>0,"Major",IF(COUNTIFS(BR5:BR80,"Minor")>0,"Minor","UNK"))) -> UNK | BS3: =IF(COUNTIFS(BS5:BS80,"CRITICAL")>0,"Critical",IF(COUNTIFS(BS5:BS80,"Major")>0,"Major",IF(COUNTIFS(BS5:BS80,"Minor")>0,"Minor","UNK"))) -> UNK | BT3: =IF(COUNTIFS(BT5:BT80,"CRITICAL")>0,"Critical",IF(COUNTIFS(BT5:BT80,"Major")>0,"Major",IF(COUNTIFS(BT5:BT80,"Minor")>0,"Minor","UNK"))) -> UNK | BV3: =IF(COUNTIFS(BV5:BV80,"CRITICAL")>0,"Critical",IF(COUNTIFS(BV5:BV80,"Major")>0,"Major",IF(COUNTIFS(BV5:BV80,"Minor")>0,"Minor","UNK"))) -> UNK | BW3: =IF(COUNTIFS(BW5:BW80,"CRITICAL")>0,"Critical",IF(COUNTIFS(BW5:BW80,"Major")>0,"Major",IF(COUNTIFS(BW5:BW80,"Minor")>0,"Minor","UNK"))) -> UNK | BX3: =IF(COUNTIFS(BX5:BX80,"CRITICAL")>0,"Critical",IF(COUNTIFS(BX5:BX80,"Major")>0,"Major",IF(COUNTIFS(BX5:BX80,"Minor")>0,"Minor","UNK"))) -> UNK | BY3: =IF(COUNTIFS(BY5:BY80,"CRITICAL")>0,"Critical",IF(COUNTIFS(BY5:BY80,"Major")>0,"Major",IF(COUNTIFS(BY5:BY80,"Minor")>0,"Minor","UNK"))) -> UNK | BZ3: =IF(COUNTIFS(BZ5:BZ80,"CRITICAL")>0,"Critical",IF(COUNTIFS(BZ5:BZ80,"Major")>0,"Major",IF(COUNTIFS(BZ5:BZ80,"Minor")>0,"Minor","UNK"))) -> UNK | CA3: =IF(COUNTIFS(CA5:CA80,"CRITICAL")>0,"Critical",IF(COUNTIFS(CA5:CA80,"Major")>0,"Major",IF(COUNTIFS(CA5:CA80,"Minor")>0,"Minor","UNK"))) -> UNK | CC3: =IF(COUNTIFS(CC5:CC80,"CRITICAL")>0,"Critical",IF(COUNTIFS(CC5:CC80,"Major")>0,"Major",IF(COUNTIFS(CC5:CC80,"Minor")>0,"Minor","UNK"))) -> UNK | CD3: =IF(COUNTIFS(CD5:CD80,"CRITICAL")>0,"Critical",IF(COUNTIFS(CD5:CD80,"Major")>0,"Major",IF(COUNTIFS(CD5:CD80,"Minor")>0,"Minor","UNK"))) -> UNK | CE3: =IF(COUNTIFS(CE5:CE80,"CRITICAL")>0,"Critical",IF(COUNTIFS(CE5:CE80,"Major")>0,"Major",IF(COUNTIFS(CE5:CE80,"Minor")>0,"Minor","UNK"))) -> UNK | CF3: =IF(COUNTIFS(CF5:CF80,"CRITICAL")>0,"Critical",IF(COUNTIFS(CF5:CF80,"Major")>0,"Major",IF(COUNTIFS(CF5:CF80,"Minor")>0,"Minor","UNK"))) -> UNK
A4: =#REF! -> #REF!
A5: =#REF! -> #REF! | B5: =#REF! -> #REF! | C5: =#REF! -> #REF! | D5: UM1-UM5 | E5: =IF(COUNTIFS(F5:CF5,"F")+COUNTIFS(F5:CF5,"NT")>0,"In Test",IF(COUNTIFS(F5:CF5,"P")+COUNTIFS(F5:CF5,"A")>0,"Pass","Pending")) -> Pending | F5: ="Pass: "& COUNTIFS(G5:CG5,"P")& " /Accept: "& COUNTIFS(G5:CG5,"A")& "/ Fail: "& COUNTIFS(G5:CG5,"Fail") & "/ NT: "& COUNTIFS(G5:CG5,"NT") -> Pass: 0 /Accept: 0/ Fail: 0/ NT: 0 | G5: =IF(#REF!<>"N/A",Priority!$C5,"") -> #REF! | H5: =IF(#REF!<>"N/A",Priority!$C5,"") -> #REF! | I5: =IF(#REF!<>"N/A",Priority!$C5,"") -> #REF! | J5: =IF(#REF!<>"N/A",Priority!$C5,"") -> #REF! | K5: =IF(#REF!<>"N/A",Priority!$C5,"") -> #REF! | M5: =IF(#REF!<>"N/A",Priority!$C5,"") -> #REF! | N5: =IF(#REF!<>"N/A",Priority!$C5,"") -> #REF! | O5: =IF(#REF!<>"N/A",Priority!$C5,"") -> #REF! | P5: =IF(#REF!<>"N/A",Priority!$C5,"") -> #REF! | Q5: =IF(#REF!<>"N/A",Priority!$C5,"") -> #REF! | S5: =IF(#REF!<>"N/A",Priority!$C5,"") -> #REF! | T5: =IF(#REF!<>"N/A",Priority!$C5,"") -> #REF! | U5: =IF(#REF!<>"N/A",Priority!$C5,"") -> #REF! | V5: =IF(#REF!<>"N/A",Priority!$C5,"") -> #REF! | W5: =IF(#REF!<>"N/A",Priority!$C5,"") -> #REF! | X5: =IF(#REF!<>"N/A",Priority!$C5,"") -> #REF! | Z5: =IF(#REF!<>"N/A",Priority!$C5,"") -> #REF! | AA5: =IF(#REF!<>"N/A",Priority!$C5,"") -> #REF! | AB5: =IF(#REF!<>"N/A",Priority!$C5,"") -> #REF! | AC5: =IF(#REF!<>"N/A",Priority!$C5,"") -> #REF! | AD5: =IF(#REF!<>"N/A",Priority!$C5,"") -> #REF! | AE5: =IF(#REF!<>"N/A",Priority!$C5,"") -> #REF! | AF5: =IF(#REF!<>"N/A",Priority!$C5,"") -> #REF! | AG5: =IF(#REF!<>"N/A",Priority!$C5,"") -> #REF! | ... AI5: =IF(#REF!<>"N/A",Priority!$C5,"") -> #REF! | AK5: =IF(#REF!<>"N/A",Priority!$C5,"") -> #REF! | AL5: =IF(#REF!<>"N/A",Priority!$C5,"") -> #REF! | AM5: =IF(#REF!<>"N/A",Priority!$C5,"") -> #REF! | AN5: =IF(#REF!<>"N/A",Priority!$C5,"") -> #REF! | AO5: =IF(#REF!<>"N/A",Priority!$C5,"") -> #REF! | AP5: =IF(#REF!<>"N/A",Priority!$C5,"") -> #REF! | AQ5: =IF(#REF!<>"N/A",Priority!$C5,"") -> #REF! | AR5: =IF(#REF!<>"N/A",Priority!$C5,"") -> #REF! | ... AT5: =IF(#REF!<>"N/A",Priority!$C5,"") -> #REF! | AV5: =IF(#REF!<>"N/A",Priority!$C5,"") -> #REF! | AW5: =IF(#REF!<>"N/A",Priority!$C5,"") -> #REF! | AX5: =IF(#REF!<>"N/A",Priority!$C5,"") -> #REF! | AY5: =IF(#REF!<>"N/A",Priority!$C5,"") -> #REF! | AZ5: =IF(#REF!<>"N/A",Priority!$C5,"") -> #REF! | BA5: =IF(#REF!<>"N/A",Priority!$C5,"") -> #REF! | BB5: =IF(#REF!<>"N/A",Priority!$C5,"") -> #REF! | BD5: =IF(#REF!<>"N/A",Priority!$C5,"") -> #REF! | BE5: =IF(#REF!<>"N/A",Priority!$C5,"") -> #REF! | BF5: =IF(#REF!<>"N/A",Priority!$C5,"") -> #REF! | BG5: =IF(#REF!<>"N/A",Priority!$C5,"") -> #REF! | BH5: =IF(#REF!<>"N/A",Priority!$C5,"") -> #REF! | BI5: =IF(#REF!<>"N/A",Priority!$C5,"") -> #REF! | BJ5: =IF(#REF!<>"N/A",Priority!$C5,"") -> #REF! | BK5: =IF(#REF!<>"N/A",Priority!$C5,"") -> #REF! | BL5: =IF(#REF!<>"N/A",Priority!$C5,"") -> #REF! | BN5: =IF(#REF!<>"N/A",Priority!$C5,"") -> #REF! | BO5: =IF(#REF!<>"N/A",Priority!$C5,"") -> #REF! | BP5: =IF(#REF!<>"N/A",Priority!$C5,"") -> #REF! | BQ5: =IF(#REF!<>"N/A",Priority!$C5,"") -> #REF! | BR5: =IF(#REF!<>"N/A",Priority!$C5,"") -> #REF! | BS5: =IF(#REF!<>"N/A",Priority!$C5,"") -> #REF! | BT5: =IF(#REF!<>"N/A",Priority!$C5,"") -> #REF! | BV5: =IF(#REF!<>"N/A",Priority!$C5,"") -> #REF! | BW5: =IF(#REF!<>"N/A",Priority!$C5,"") -> #REF! | BX5: =IF(#REF!<>"N/A",Priority!$C5,"") -> #REF! | BY5: =IF(#REF!<>"N/A",Priority!$C5,"") -> #REF! | BZ5: =IF(#REF!<>"N/A",Priority!$C5,"") -> #REF! | CA5: =IF(#REF!<>"N/A",Priority!$C5,"") -> #REF! | CC5: =IF(#REF!<>"N/A",Priority!$C5,"") -> #REF! | CD5: =IF(#REF!<>"N/A",Priority!$C5,"") -> #REF! | CE5: =IF(#REF!<>"N/A",Priority!$C5,"") -> #REF! | CF5: =IF(#REF!<>"N/A",Priority!$C5,"") -> #REF!
